Workbook
Name SegmentaciónDeDatos_Año: #N/A
Name SegmentaciónDeDatos_Canal: #N/A
Name SegmentaciónDeDatos_Localidad: #N/A

Sheet Data
A1: ID Venta | B1: Fecha | C1: Producto | D1: Categoría | E1: Vendedor | F1: Localidad | G1: Canal | H1: Cantidad Vendida | I1: Precio Unitario | J1: Total Venta | K1: Mes | L1: Dia | M1: Año | N1: Digito Mes | O1: Trimestre
A2: 1 | B2: 2023-08-23 | C2: Celular | D2: Telefonía | E2: Juan Hernández | F2: Kennedy | G2: Tienda Física | H2: 12 | I2: 1778 | J2: =I2*H2 -> 21336 | K2: =TEXT(Tabla1[[#This Row],[Fecha]],"MMMM") -> August | L2: =TEXT(Tabla1[[#This Row],[Fecha]],"DD") -> 23 | M2: =TEXT(Tabla1[[#This Row],[Fecha]],"yyyy") -> 2023 | N2: =MONTH(Tabla1[[#This Row],[Fecha]]) -> 8 | O2: ="T"&ROUNDUP(MONTH(B2)/3,0)&"-"&RIGHT(YEAR(B2),2) -> T3-23
A3: 2 | B3: 2025-07-22 | C3: Memoria USB | D3: Accesorios | E3: Juan Hernández | F3: Suba | G3: Tienda Física | H3: 9 | I3: 4169 | J3: =I3*H3 -> 37521 | K3: =TEXT(Tabla1[[#This Row],[Fecha]],"MMMM") -> July | L3: =TEXT(Tabla1[[#This Row],[Fecha]],"DD") -> 22 | M3: =TEXT(Tabla1[[#This Row],[Fecha]],"yyyy") -> 2025 | N3: =MONTH(Tabla1[[#This Row],[Fecha]]) -> 7 | O3: ="T"&ROUNDUP(MONTH(B3)/3,0)&"-"&RIGHT(YEAR(B3),2) -> T3-25
A4: 3 | B4: 2023-11-04 | C4: Impresora | D4: Periféricos | E4: María López | F4: Fontibón | G4: Online | H4: 22 | I4: 4088 | J4: =I4*H4 -> 89936 | K4: =TEXT(Tabla1[[#This Row],[Fecha]],"MMMM") -> November | L4: =TEXT(Tabla1[[#This Row],[Fecha]],"DD") -> 04 | M4: =TEXT(Tabla1[[#This Row],[Fecha]],"yyyy") -> 2023 | N4: =MONTH(Tabla1[[#This Row],[Fecha]]) -> 11 | O4: ="T"&ROUNDUP(MONTH(B4)/3,0)&"-"&RIGHT(YEAR(B4),2) -> T4-23
A5: 4 | B5: 2025-09-29 | C5: Disco Duro | D5: Almacenamiento | E5: Juan Hernández | F5: Chapinero | G5: Tienda Física | H5: 3 | I5: 1909 | J5: =I5*H5 -> 5727 | K5: =TEXT(Tabla1[[#This Row],[Fecha]],"MMMM") -> September | L5: =TEXT(Tabla1[[#This Row],[Fecha]],"DD") -> 29 | M5: =TEXT(Tabla1[[#This Row],[Fecha]],"yyyy") -> 2025 | N5: =MONTH(Tabla1[[#This Row],[Fecha]]) -> 9 | O5: ="T"&ROUNDUP(MONTH(B5)/3,0)&"-"&RIGHT(YEAR(B5),2) -> T3-25
A6: 5 | B6: 2025-02-19 | C6: Mouse | D6: Accesorios | E6: María López | F6: Chapinero | G6: Online | H6: 20 | I6: 1092 | J6: =I6*H6 -> 21840 | K6: =TEXT(Tabla1[[#This Row],[Fecha]],"MMMM") -> February | L6: =TEXT(Tabla1[[#This Row],[Fecha]],"DD") -> 19 | M6: =TEXT(Tabla1[[#This Row],[Fecha]],"yyyy") -> 2025 | N6: =MONTH(Tabla1[[#This Row],[Fecha]]) -> 2 | O6: ="T"&ROUNDUP(MONTH(B6)/3,0)&"-"&RIGHT(YEAR(B6),2) -> T1-25
A7: 6 | B7: 2024-04-10 | C7: Disco Duro | D7: Almacenamiento | E7: Carlos Gómez | F7: Engativá | G7: Tienda Física | H7: 21 | I7: 4473 | J7: =I7*H7 -> 93933 | K7: =TEXT(Tabla1[[#This Row],[Fecha]],"MMMM") -> April | L7: =TEXT(Tabla1[[#This Row],[Fecha]],"DD") -> 10 | M7: =TEXT(Tabla1[[#This Row],[Fecha]],"yyyy") -> 2024 | N7: =MONTH(Tabla1[[#This Row],[Fecha]]) -> 4 | O7: ="T"&ROUNDUP(MONTH(B7)/3,0)&"-"&RIGHT(YEAR(B7),2) -> T2-24
A8: 7 | B8: 2025-05-05 | C8: Mouse | D8: Accesorios | E8: Juan Hernández | F8: Usaquén | G8: Online | H8: 5 | I8: 2863 | J8: =I8*H8 -> 14315 | K8: =TEXT(Tabla1[[#This Row],[Fecha]],"MMMM") -> May | L8: =TEXT(Tabla1[[#This Row],[Fecha]],"DD") -> 05 | M8: =TEXT(Tabla1[[#This Row],[Fecha]],"yyyy") -> 2025 | N8: =MONTH(Tabla1[[#This Row],[Fecha]]) -> 5 | O8: ="T"&ROUNDUP(MONTH(B8)/3,0)&"-"&RIGHT(YEAR(B8),2) -> T2-25
A9: 8 | B9: 2024-07-15 | C9: Laptop | D9: Computadores | E9: Carlos Gómez | F9: Engativá | G9: Online | H9: 2 | I9: 4228 | J9: =I9*H9 -> 8456 | K9: =TEXT(Tabla1[[#This Row],[Fecha]],"MMMM") -> July | L9: =TEXT(Tabla1[[#This Row],[Fecha]],"DD") -> 15 | M9: =TEXT(Tabla1[[#This Row],[Fecha]],"yyyy") -> 2024 | N9: =MONTH(Tabla1[[#This Row],[Fecha]]) -> 7 | O9: ="T"&ROUNDUP(MONTH(B9)/3,0)&"-"&RIGHT(YEAR(B9),2) -> T3-24
A10: 9 | B10: 2024-03-28 | C10: Celular | D10: Telefonía | E10: María López | F10: Chapinero | G10: Tienda Física | H10: 15 | I10: 4814 | J10: =I10*H10 -> 72210 | K10: =TEXT(Tabla1[[#This Row],[Fecha]],"MMMM") -> March | L10: =TEXT(Tabla1[[#This Row],[Fecha]],"DD") -> 28 | M10: =TEXT(Tabla1[[#This Row],[Fecha]],"yyyy") -> 2024 | N10: =MONTH(Tabla1[[#This Row],[Fecha]]) -> 3 | O10: ="T"&ROUNDUP(MONTH(B10)/3,0)&"-"&RIGHT(YEAR(B10),2) -> T1-24
A11: 10 | B11: 2023-08-14 | C11: Memoria USB | D11: Accesorios | E11: Ana Pérez | F11: Teusaquillo | G11: Online | H11: 17 | I11: 3882 | J11: =I11*H11 -> 65994 | K11: =TEXT(Tabla1[[#This Row],[Fecha]],"MMMM") -> August | L11: =TEXT(Tabla1[[#This Row],[Fecha]],"DD") -> 14 | M11: =TEXT(Tabla1[[#This Row],[Fecha]],"yyyy") -> 2023 | N11: =MONTH(Tabla1[[#This Row],[Fecha]]) -> 8 | O11: ="T"&ROUNDUP(MONTH(B11)/3,0)&"-"&RIGHT(YEAR(B11),2) -> T3-23
A12: 11 | B12: 2025-07-10 | C12: Memoria USB | D12: Accesorios | E12: Laura Torres | F12: Engativá | G12: Tienda Física | H12: 9 | I12: 3052 | J12: =I12*H12 -> 27468 | K12: =TEXT(Tabla1[[#This Row],[Fecha]],"MMMM") -> July | L12: =TEXT(Tabla1[[#This Row],[Fecha]],"DD") -> 10 | M12: =TEXT(Tabla1[[#This Row],[Fecha]],"yyyy") -> 2025 | N12: =MONTH(Tabla1[[#This Row],[Fecha]]) -> 7 | O12: ="T"&ROUNDUP(MONTH(B12)/3,0)&"-"&RIGHT(YEAR(B12),2) -> T3-25
A13: 12 | B13: 2025-04-30 | C13: Tablet | D13: Computadores | E13: Carlos Gómez | F13: Engativá | G13: Online | H13: 6 | I13: 3210 | J13: =I13*H13 -> 19260 | K13: =TEXT(Tabla1[[#This Row],[Fecha]],"MMMM") -> April | L13: =TEXT(Tabla1[[#This Row],[Fecha]],"DD") -> 30 | M13: =TEXT(Tabla1[[#This Row],[Fecha]],"yyyy") -> 2025 | N13: =MONTH(Tabla1[[#This Row],[Fecha]]) -> 4 | O13: ="T"&ROUNDUP(MONTH(B13)/3,0)&"-"&RIGHT(YEAR(B13),2) -> T2-25
... A401: 400 | B401: 2024-05-27 | C401: Teclado | D401: Accesorios | E401: María López | F401: Teusaquillo | G401: Tienda Física | H401: 2 | I401: 1298 | J401: =I401*H401 -> 2596 | K401: =TEXT(Tabla1[[#This Row],[Fecha]],"MMMM") -> May | L401: =TEXT(Tabla1[[#This Row],[Fecha]],"DD") -> 27 | M401: =TEXT(Tabla1[[#This Row],[Fecha]],"yyyy") -> 2024 | N401: =MONTH(Tabla1[[#This Row],[Fecha]]) -> 5 | O401: ="T"&ROUNDUP(MONTH(B401)/3,0)&"-"&RIGHT(YEAR(B401),2) -> T2-24

Sheet Tablas Dinamicas
B4: Etiquetas de fila | C4: Suma de Total Venta | E4: Etiquetas de fila | F4: Cuenta de ID Venta | J4: Etiquetas de fila | K4: Suma de Total Venta
B5: 2023 | C5: 4502363 | E5: Laptop | F5: 39 | J5: Chapinero | K5: 2110135
B6: 2024 | C6: 3869552 | E6: Memoria USB | F6: 40 | J6: Engativá | K6: 1783681
B7: 2025 | C7: 4233217 | E7: Mouse | F7: 47 | J7: Fontibón | K7: 1493602
B8: Total general | C8: 12605132 | E8: Impresora | F8: 48 | J8: Kennedy | K8: 1207317
E9: Celular | F9: 56 | J9: Suba | K9: 1723792
E10: Total general | F10: 230 | J10: Teusaquillo | K10: 2308762
J11: Usaquén | K11: 1977843
J12: Total general | K12: 12605132
E20: Etiquetas de fila | F20: Cuenta de ID Venta | J20: Calculos auxiliares
E21: Auriculares | F21: 31 | I21: Ticket promedio | J21: =GETPIVOTDATA("Total Venta",$B$4)/GETPIVOTDATA("ID Venta",$E$20) -> 31512.83
E22: Tablet | F22: 31 | I22: Productos activos | J22: =COUNTA(_xlfn.UNIQUE(Tabla1[Producto])) -> 10
E23: Monitor | F23: 33 | I23: Total transacciones | J23: =COUNTA(_xlfn.UNIQUE(Tabla1[[#All],[ID Venta]]))-1 -> 400
E24: Teclado | F24: 37 | I24: Ventas 2023 | J24: =SUMIF(Tabla1[Año],2023,Tabla1[Total Venta]) -> 4502363
E25: Disco Duro | F25: 38 | I25: Ventas 2024 | J25: =SUMIF(Tabla1[Año],2024,Tabla1[Total Venta]) -> 3869552
E26: Laptop | F26: 39 | I26: Ventas 2025 | J26: =SUMIF(Tabla1[Año],2025,Tabla1[Total Venta]) -> 4233217
E27: Memoria USB | F27: 40
E28: Mouse | F28: 47 | I28: Total general | J28: =SUM(J24:J26) -> 12605132
E29: Impresora | F29: 48
E30: Celular | F30: 56 | I30: Calculo 2024 vs 2023 | J30: =(J25-J24)/J24 -> -0.14055086
E31: Total general | F31: 400 | I31: Calculo 2025 vs 2024 | J31: =(J26-J25)/J25 -> 0.093981164
I33: Transacciones 2024 | J33: =COUNTIFS(Tabla1[ID Venta], "<>"&"",Tabla1[Año],2024) -> 118
I34: Transacciones 2025 | J34: =COUNTIFS(Tabla1[ID Venta], "<>"&"",Tabla1[Año],2025) -> 142
J35: =(J34-J33)/J33 -> 0.20338983
I38: T promedio 2024 | J38: =J25/J33 -> 32792.814
I39: T promedio 2025 | J39: =J26/J34 -> 29811.387
I40: Ticket promedio general | J40: =J28/GETPIVOTDATA("ID Venta",$E$20) -> 31512.83
J41: =(J39-J38)/J38 -> -0.090917061
I43: Producto top | J43: {=INDEX(Tabla1[Producto],MATCH(MAX(COUNTIF(Tabla1[Producto],Tabla1[Producto])),COUNTIF(Tabla1[Producto],Tabla1[Producto]),0))} -> Celular
C44: Etiquetas de fila | D44: Suma de Total Venta | I44: Cantidad producto top | J44: {=MAX(COUNTIF(Tabla1[Producto],Tabla1[Producto]))} -> 56
C45: T1-23 | D45: 1006238
C46: T1-24 | D46: 1024795 | I46: Ventas tienda física | J46: =SUMIF(Tabla1[Canal],"Tienda Física",Tabla1[Total Venta]) -> 5901672
C47: T1-25 | D47: 1092261 | I47: Ventas tienda online | J47: =SUMIF(Tabla1[Canal],"Online",Tabla1[Total Venta]) -> 6703460
C48: T2-23 | D48: 1186006 | J48: =J46/J28 -> 0.46819597
C49: T2-24 | D49: 805668 | J49: =J47/J28 -> 0.53180403
C50: T2-25 | D50: 925111
C51: T3-23 | D51: 1067991
C52: T3-24 | D52: 1067946
C53: T3-25 | D53: 1062105
C54: T4-23 | D54: 1242128
...

Sheet Dashboard
K2: Análisis de ventas Bogotá
K5: Período 2023-2025 | Dashboard Ejecutivo
K8: VENTAS TOTALES | AB8: TRANSACCIONES | AP8: TICKET PROMEDIO | BG8: PRODUCTOS ACTIVOS
K10: =GETPIVOTDATA("Total Venta",'Tablas Dinamicas'!$B$4) -> 12605132 | AB10: =GETPIVOTDATA("ID Venta",'Tablas Dinamicas'!$E$20) -> 400 | AP10: ='Tablas Dinamicas'!J21 -> 31512.83 | BG10: ='Tablas Dinamicas'!J22 -> 10
K13: =IF('Tablas Dinamicas'!J31>0,"↑ ","↓ ")&TEXT(ABS('Tablas Dinamicas'!J31),"0.0%")&" vs 2024" -> ↑ 9.4% vs 2024 | AB13: =IF('Tablas Dinamicas'!J35>0,"↑ ","↓ ")&TEXT(ABS('Tablas Dinamicas'!J35),"0.0%")&" vs 2024" -> ↑ 20.3% vs 2024 | AP13: =IF('Tablas Dinamicas'!J41>0,"↑ ","↓ ")&TEXT(ABS('Tablas Dinamicas'!J41),"0.0%")&" vs 2024" -> ↓ 9.1% vs 2024 | BG13: ="Top: "&'Tablas Dinamicas'!J43&" ("&'Tablas Dinamicas'!J44&")" -> Top: Celular (56)
K16: INSIGHTS CLAVE
L18: ='Tablas Dinamicas'!J43&" lidera con "&'Tablas Dinamicas'!J44&" ventas ("&TEXT('Tablas Dinamicas'!J44/'Tablas Dinamicas'!J23,"0%")&" del total)" -> Celular lidera con 56 ventas (14% del total)
L20: ="Tienda Online genera "&TEXT('Tablas Dinamicas'!J49,"0%")&" vs tienda Física "&TEXT('Tablas Dinamicas'!J48,"0%") -> Tienda Online genera 53% vs tienda Física 47%
L22: 2023 fue el mejor año: $4.5M en ingresos
L24: Top localidades: Teusaquillo y Chapinero
L26: Canal Físico tiene mejor ticket promedio
L28: Aumentar presencia en Tienda Física en Kennedy
